Workbook
Name 走水平衡X轴: OFFSET(多型腔平衡测试!$A$19,COUNTIF(多型腔平衡测试!$B$20:$B$531,">0"),0,-COUNTIF(多型腔平衡测试!$B$20:$B$531,">0"),1)
Name 走水平衡Y轴: OFFSET(多型腔平衡测试!$B$19,COUNTIF(多型腔平衡测试!$B$20:$B$531,">0"),0,-COUNTIF(多型腔平衡测试!$B$20:$B$531,">0"),1)

Sheet 目录
A2: =IF(G2="中文",对照!B3,IF(G2="English",对照!C3,对照!B3)) -> 模号 | C2: =IF(G2="中文",对照!B4,IF(G2="English",对照!C4,对照!B4)) -> 试模目的 | E2: =IF(G2="中文",对照!B5,IF(G2="English",对照!C5,对照!B5)) -> 试模时间 | G2: 中文
B4: =IF(G2="中文",对照!B6,IF(G2="English",对照!C6,对照!B6)) -> 模具验证测试总结报告
B5: =IF(G2="中文",对照!B7,IF(G2="English",对照!C7,对照!B7)) -> 模具表现评估表
B6: =IF(G2="中文",对照!B13,IF(G2="English",对照!C13,对照!B13)) -> 试模参数记录
B7: =IF(G2="中文",对照!B25,IF(G2="English",对照!C25,对照!B25)) -> 模具问题点履历表
B8: =IF(G2="中文",对照!B15,IF(G2="English",对照!C15,对照!B15)) -> 模具运水状况报告
B9: =IF(G2="中文",对照!B16,IF(G2="English",对照!C16,对照!B16)) -> 模具冷却均匀性测试
B10: =IF(G2="中文",对照!B17,IF(G2="English",对照!C17,对照!B17)) -> 注射速度优化
B11: =IF(G2="中文",对照!B18,IF(G2="English",对照!C18,对照!B18)) -> 走水平衡分析
B12: =IF(G2="中文",对照!B19,IF(G2="English",对照!C19,对照!B19)) -> 压力损失报告
B13: =IF(G2="中文",对照!B20,IF(G2="English",对照!C20,对照!B20)) -> 保压压力测试报告
B14: =IF(G2="中文",对照!B21,IF(G2="English",对照!C21,对照!B21)) -> 保压时间优化
B15: =IF(G2="中文",对照!B22,IF(G2="English",对照!C22,对照!B22)) -> 冷却时间优化
B16: =IF(G2="中文",对照!B23,IF(G2="English",对照!C23,对照!B23)) -> 锁模力优化报告
B17: =IF(G2="中文",对照!B24,IF(G2="English",对照!C24,对照!B24)) -> 周期时间优化报告

Sheet 对照
A1: Sheet | B1: 中文 | C1: 英文 | D1: Sheet | E1: 中文 | F1: 英文 | G1: Sheet | H1: 中文 | I1: 英文 | J1: Sheet | K1: 中文 | L1: 英文 | M1: Sheet | N1: 中文 | O1: 英文 | P1: Sheet | Q1: 中文 | R1: 英文 | S1: Sheet | T1: 中文 | U1: 英文 | V1: Sheet | W1: 中文 | X1: 英文 | Y1: Sheet | Z1: 中文 | AA1: 英文 | AB1: Sheet | AC1: 中文 | AD1: 英文 | AE1: Sheet | AF1: 中文 | AG1: 英文 | AH1: Sheet | AI1: 中文 | AJ1: 英文 | AK1: Sheet | AL1: 中文 | AM1: 英文 | AN1: Sheet | AO1: 中文 | AP1: 英文 | AQ1: Sheet | AR1: 中文 | AS1: 英文 | AT1: Sheet | AU1: 中文 | AV1: 英文 | AW1: Sheet | AX1: 中文 | AY1: 英文 | AZ1: Sheet | BA1: 中文 | BB1: 英文 | BC1: Sheet | BD1: 中文 | BE1: 英文 | BF1: Sheet | BG1: 中文 | BH1: 英文 | BI1: Sheet | BJ1: 中文 | BK1: 英文 | BL1: Sheet | BM1: 中文 | BN1: 英文 | BO1: Sheet | BP1: 中文 | BQ1: 英文
A2: Catalogue | B2: 目录 | C2: Catalogue | D2: 模具验证测试总结报告 | E2: 模具验证测试总结报告 | F2: Mold Test Summary Report | G2: 模具表现评估表 | H2: 模具表现评估表 | J2: 模具信息 | K2: 模具信息 | L2: Mold Information | M2: 注塑机信息 | N2: 注塑机信息 | O2: Inject Machine Information | P2: 胶料在料筒中停留时间 | Q2: 胶料在料筒中停留时间 | R2: Residence Time | S2: 炮筒利用率 | T2: 炮筒利用率 | U2: Barrel Utilization % | V2: 照片&视频 | W2: 照片&视频 | X2: Photo&Video | Y2: 试模参数记录 | Z2: 试模参数记录表 | AA2: Trial Report | AB2: 试模参数记录(双色) | AC2: 试模参数记录表 | AD2: Trial Report | AE2: 模具运水状况测试 | AF2: 模具运水状况报告 | AG2: Water Flow Rate Report | AH2: 模具冷却均匀性测试 Water Circuit Temperature Report | AI2: 模具冷却均匀性测试 Water Circuit Temperature Report | AJ2: Water Circuit Temperature Report | AK2: 注射注射速度优化报告 Optimized Injection Speed Report速度优化 | AL2: 注射速度优化报告 Optimized Injection Speed Report | AM2: Optimized Injection Speed Report | AN2: 走水平衡分析报告 | AO2: 走水平衡分析报告 Short Shot Balance Report | AP2: Short Shot Balance Report | AQ2: 压力损失报告 | AR2: 压力损失报告 Pressure Loss Report | AS2: Pressure Loss Report | AT2: 保压压力测试报告 | AU2: 保压压力测试报告 Holding Pressure Test Report | AV2: Holding Pressure Test Report | AW2: 保压时间优化 | AX2: 保压时间优化 Optimized Holding Time Report | AY2: Optimized Holding Time Report | AZ2: 冷却时间优化报告 | BA2: 冷却时间优化报告 Optimized Cooling Time Report | BB2: Optimized Cooling Time Report | BC2: 锁模力优化报告 | BD2: 锁模力优化报告 Optimized Clamp Force Report | BE2: Optimized Clamp Force Report | BF2: 周期时间优化报告 | BG2: 周期时间优化报告 Optimized Cycle Time Report | BH2: Optimized Cycle Time Report | BI2: 模具问题点履历表 | BJ2: 模具问题点履历表 | BK2: Mold Open Issue Record | BL2: 可容许度测试报告 | BM2: 可容许度测试报告 Acceptability Test Report | BN2: Acceptability Test Report | BO2: 模具表现评估 | BP2: 模具表现评估 | BQ2: Mold Performance Check List
B3: 模号 | C3: Mold number | E3: 模号 Mold Number | F3: Mold Number | H3: 检查项目 | I3: Check Item | K3: 模具尺寸 | L3: Mold Size | N3: 注塑机型号 | O3: Machine | Q3: 停留时间计算 | R3: Residence Time | T3: 炮筒直径(mm) | U3: Barrel Diameter (mm) | W3: 模具照片 | X3: Mold Photo | Z3: 基本信息 | AA3: Information | AC3: 射胶 1st | AD3: Injection 1st | AF3: 组号 Group No. | AG3: Group No. | AI3: 型腔 | AJ3: Cavity Side | AL3: 机型 Injection Machine | AM3: Injection Machine | AO3: 填充95% | AP3: Fill 95% | AR3: 流经位置 Flow analysis | AS3: Flow analysis | AU3: 优化操作者 Operator | AV3: Operator | AX3: 优化结果 Optimized result | AY3: Optimized result | BA3: 优化冷却时间 Optimized Cooling Time | BB3: Optimized Cooling Time | BD3: 优化的锁模力 Opt. clamp force | BE3: Opt. clamp force | BG3: 目标周期时间 | BH3: Target Cycle | BJ3: 问题点 | BK3: Mold problem | BM3: 注塑参数 | BN3: Parameters | BP3: 模 号: | BQ3: Mold No.
B4: 试模目的 | C4: Purpose | E4: 测试时间 Test Date | F4: Trial Date | H4: 检查细则 | I4: Check Detail | K4: 模具法兰直径 | L4: Mold Flange Diameter | N4: 注塑机类型 | O4: Machine type | Q4: 这是一种经验法则，在业内被认可。 | R4: This is a "Rule of thumb" calculation. Commonly accepted in industry, but does not include material in screw flights | T4: 炮筒最大体积 | U4: Barrel Max. Shot Volume (gr) | W4: 样板及走水照片 | X4: Sample&Fill Study Photo | Z4: 模号 | AA4: Mold number | AC4: 射胶 2nd | AD4: Injection 2nd | AF4: 出水方向/ out put | AG4: out put | AI4: 型芯 | AJ4: Core Side | AL4: 注射时间 Injection time | AM4: Injection time | AO4: 型腔 Cavity | AP4: Cavity | AR4: 实际注射压力 Actual Injection Pressure | AS4: Actual Injection Pressure | AU4: 优化日期 Date | AV4: Date | AX4: 在已优化的保压压力下优化保压时间 Optimized holding time at optimum holding pressure: | AY4: Optimized holding time at optimum holding pressure: | BA4: 外观描述 Appearance description | BB4: Appearance description | BD4: 当前最大保压压力 Cur. Max. Hld. Pres. | BE4: Cur. Max. Hld. Pres. | BG4: 实际周期时间 | BH4: Actual Time | BJ4: 遗留问题点 | BK4: Remaining problems | BM4: 外观 | BN4: Observation | BP4: 制作工程师: | BQ4: Tooling Engineer:
B5: 试模时间 | C5: Date | E5: 模具工程师 Molding Engineer | F5: Molding Engineer | H5: 评估结果 | I5: Result | K5: 开模行程 | L5: Open Stroke | N5: 主射台 | O5: Main Injection Init | Q5: Input - Barrel Diameter( 螺杆直径): | R5: Input - Barrel Diameter | T5: 每啤最大体积 | U5: Tool Full Shot Volume (gr) | W5: 模具温度、热流道温度照片 | X5: Temperature Photo | Z5: 客户 | AA5: Customer | AC5: 保压 1st | AD5: Holding pressure 1st | AF5: 运水直径 （mm） | AG5: Diameter of Cooling circuit（mm） | AI5: Operator Side 操作侧 | AJ5: Operator Side | AL5: 注射压力 Injection pressure | AM5: Injection pressure | AO5: 重量(g) Weight(g) | AP5: Weight(g) | AR5: 单位 Unit | AS5: Unit | AU5: 当前设定锁模力 Current setting clamp force | AV5: Current setting clamp force | AX5: 压时间 (s) Holding time (s) | AY5: Holding time (s) | BD5: 注塑机最高锁模力 Max. clamp force | BE5: Max. clamp force | BG5: 计算周期时间 | BH5: Calculate Time | BJ5: 新增问题点 | BK5: New problems | BM5: 重要尺寸 | BN5: Key Size | BP5: 审 核: | BQ5: Aprroved by:
B6: 模具验证测试总结报告 | C6: Molding Test Summart Report | E6: 项目工程师 Project Engineer | F6: Project Engineer | H6: 处理方法 及项目号 | K6: 唧咀球半径SR | L6: Sphere Diameter | N6: 机器法兰孔直径 | O6: Machine Flange Diameter | Q6: Input - Maximum Barrel Stroke(螺杆最大行程): | R6: Input - Maximum Barrel Stroke | T6: 最佳工作范围 | U6: opt. working range | W6: 周边照片 | X6: Auxiliary Equipmet | Z6: 机型 | AA6: Machine | AC6: 保压 2nd | AD6: Holding pressure 2nd | AF6: 水的温度 （℃） | AG6: Water temperature（℃） | AI6: 实测温度 | AJ6: Actual Temperature | AL6: 注射速度 Injection Speed | AM6: Injection Speed | AO6: 最大重量 Maximum weight | AP6: Maximum weight | AR6: 各部位压力损失 | AU6: 序号 Item | AV6: Item | AX6: 平均重量 (g) Average weight (g) | AY6: Average weight (g) | BD6: 理论计算的锁模力 Theory clamp force | BE6: Theory clamp force | BG6: 从注塑机上采集真实值 | BJ6: 备注 | BK6: Remark | BM6: 上差 | BN6: up | BP6: 试模员: | BQ6: Operator:
B7: 模具表现评估表 | C7: Mold Performance Check List | E7: A. 模具问题点描述/Mold issue: | F7: A. Mold issue： | H7: 签名确认 | K7: 拉杆螺纹 | L7: Puck Size | N7: 射咀球径 | O7: Nozzle Sphere Diameter | Q7: Input - Hot sprue or Manifold Volume if applicable (cm^3)(热流道熔胶的体积) | R7: Input - Hot sprue or Manifold Volume if applicable (cm^3) | T7: 可接受的范围 | U7: conditional suited | W7: 视频 | X7: Video | Z7: 干燥方法 | AA7: Dry method | AC7: 监测项目 1st | AD7: Tail Item 1st | AF7: 流量 (g/m) | AG7: Water flow rate (g/m) | AL7: 剪切速率 Shear rate | AM7: Shear rate | AO7: 最小重量 Minimum weight | AP7: Minimum weight | AR7: 填充部位 | AU7: 保压压力 Holding pressure | AV7: Holding pressure | AX7: 冷却时间 (s) Cooling time (s) | AY7: Cooling time (s) | BD7: 锁模力 Clamp force | BE7: Clamp force | BG7: 注射时间 | BH7: Fill Time | BJ7: 工程师 | BK7: Mold Engineer | BM7: 下差 | BN7: down | BP7: 试模次数 | BQ7: Trial times：
B8: 模具信息 | C8: Mold Information | E8: 模具判定: Result of mold: | F8: Result of mold: | H8: 第一部分: 模具动作和功能 | K8: 顶棍孔直径 | L8: Ejector Hole Diameter | N8: 副射台 | O8: Secondary Injection Init | Q8: Output - Total shot Volume( 总的熔胶体积) | R8: Output - Total shot Volume | T8: 不推荐的范围 | U8: not recommended | W8: 模具参数 | X8: Mold Parameters | Z8: 干燥温度(℃) | AA8: Dry temp.(℃) | AC8: 监测项目 2nd | AD8: Tail Item 2nd | AF8: 水的压力 (kgf/cm²) | AG8: Water Pressure (kgf/cm²) | AL8: 有效粘度 Relative Viscosity | AM8: Relative Viscosity | AO8: 平衡度 Balance | AP8: Balance | AR8: 喷嘴-流道 | AU8: 单位 Unit | AV8: Unit | AX8: 产品重量 Product weight (g) | AY8: Product weight (g) | BD8: 平均重量 Average weight | BE8: Average weight | BG8: 保压时间 | BH8: Hold Pressure | BJ8: 试模员 | BK8: Reporter | BM8: 射胶速度 | BN8: Inj.Speed | BP8: 试模日期: | BQ8: Trial Date:
B9: 注塑机信息 | C9: Inject Machine Information | E9: B. 产品问题点描述/Part issue： | F9: B. Part issue： | H9: 开合模动作顺畅无异响 | K9: 顶棍孔分布 | L9: Ejector Position | N9: 合模部件 | O9: Clamping parts | Q9: Melt Density of(原料的密度): | R9: Melt Density of | T9: 每啤重量 | U9: Tool Full Shot Weight | Z9: 干燥时间(h) | AA9: Dry time(h) | AC9: 阀针 | AD9: Valve | AF9: 水的粘度系数 (10-6m²/s) | AG9: Kinematic viscosity (10-6m²/s) | AL9: 相对粘度差异 Change in Relative Viscosity | AM9: Change in Relative Viscosity | AO9: 判定结果 Result | AP9: Result | AR9: 流道-浇口 | AU9: 制品外观描述 Explanation | AV9: Explanation | BD9: 产品重量 Product weight | BE9: Product weight | BG9: 冷却时间 | BH9: Cooling Time | BM9: 优化参数 | BN9: Opt. Parameters | BP9: 检查项目 | BQ9: Items
B10: 胶料停留时间 | C10: Residence Time | E10: 塑胶产品判定: Result of part: | F10: Result of part: | H10: 顶出/复位顺畅无异响 | K10: 热流道 | L10: Hot Runner | N10: 最大合模力 | O10: Nax Clamping Force | Q10: Input - Material density from list above( 原料的密度): | R10: Input - Material density from list above | T10: 密度 | U10: Density | Z10: 胶料 | AA10: Dry time(h) | AF10: 雷诺系数 | AG10: Reynolds Nunber | AL10: 折线 | AM10: Polyline | AR10: 浇口-10%～30%产品 | AU10: 制品重量（g） Product weight | AV10: Product weight | BD10: 质量描述 Quality description | BE10: Quality description | BG10: 开模时间 | BH10: Open Time | BM10: 保压压力 | BN10: Holding Pressure | BP10: 检查细则 | BQ10: Description
B11: 料筒利用率 | C11: Barrel Utilization % | E11: C. 改善措施/Corrective or Improvement action | F11: Corrective or Improvement action | H11: 行位动作顺畅无异响 | K11: 冷流道 | L11: Cold Runner | N11: 最大开模行程 | O11: Max Open Stroke | Q11: Output - Grams of material in the barrel(料管內原料的重量): | R11: Output - Grams of material in the barrel | Z11: 颜色 | AA11: Color | AF11: 结果 | AG11: Result | AL11: 斜率 | AM11: Slope | AR11: 浇口-30%～60%产品 | AU11: 流动分析图片 Flow analysis photos: | AV11: Flow analysis photos: | BG11: 取产品时间 | BH11: Pick Time | BM11: 冷却时间 | BN11: Cooling Time | BP11: 评估结果 | BQ11: Result
B12: 照片&视频 | C12: Photo&Video | E12: 试模参数判定: Result of part: | F12: Result of part: | H12: 油唧动作顺畅无异响 | K12: 封针 | L12: Needle Sealing | N12: 模板尺寸(L) | O12: Template Size(L) | Q12: Input - Cycle Time (周期sec) | R12: Input - Cycle Time | Z12: 试模次数 | AA12: Trial times | AR12: 浇口-60%～90%产品 | BG12: 机械手取件时间 | BH12: Mechanical Hand | BM12: 模具温度 | BN12: Mold temperature
B13: 试模参数记录 | C13: Mold Trial Report | E13: D.模具验证测试结果最终确认/Final Result： | F13: Final Result： | H13: 热咀封针/热流道无不良 | K13: 油路组数 | L13: Oil Num | N13: 模板尺寸(H) | O13: Template Size(H) | Q13: Input - Part shot weight in grams( 产品的重量): | R13: Input - Part shot weight in grams | Z13: 型腔数 | AA13: Cavity number | AR13: 压力损失（kg/cm^2) | BG13: 合模时间 | BH13: Close Time | BM13: 前模 | BN13: Cav | BP13: 签名确认 | BQ13: Signature
B14: 试模参数记录表(双色) | C14: Mold Trial Report（double） | E14: 注/Note: | F14: Note: | H14: 平面顶针能转动 | K14: 模具动作及特别注意事项 | L14: Notation | N14: 模具最小尺寸 | O14: Min Mold Size | Q14: Input - Cold runner weight in grams(冷流道的重量): | R14: Input - Cold runner weight in grams | Z14: 射嘴孔直径 | AA14: Injection sprue Dia. | AR14: 压力损失曲线Pressure loss curve | AS14: Pressure loss curve | BG14: 所有周期时间 | BH14: Cycle Time | BM14: 后模 | BN14: Cor | BP14: 处理方法 | BQ14: Method
B15: 模具运水状况报告 | C15: Water Flow Rate Report | E15: 1. 模具验证测试结果判定合格标准为流道浇口在修模中不需要加大，模具验证测试完成；反之就可判定不合格。 | F15: 1. As long as the runner and gate dimensions are suitable and the test is completed, the test result is judged as qualified. | H15: 产品/水口取件符合要求 | K15: 1. 此模分 次开模，开模顺序见结构简图。 | L15: Notation One | N15: 模具最大尺寸 | O15: Max Mold Size | Q15: Input - # of cavities(穴数): | R15: Input - # of cavities | Z15: 螺杆直径 | AA15: Screw diameter | AR15: 流动分析图片 Flow analysis photos | AS15: Flow analysis photos | BG15: 已优化的 | BH15: Optimized | BM15: 判定结果 | BN15: Result | BP15: 第二部分:模具动作和功能 | BQ15: Part II:Mold Function
B16: 模具冷却均匀性测试 | C16: Water Circuit Temperature Report | E16: 2.品质工程师发出此报告后，项目工程师若对表格内容有疑义的，项目工程师需及时给予书面回复。 | F16: 2. Any doubts about the content of the form, the PE shall reply in writing ASAP. | H16: 第二部分: 制作工艺 | K16: 2. 油唧抽芯动作的先后顺序见示意图。 | L16: Notation Two | N16: 模具最大厚度 | O16: Max Mold Thickness | Q16: Output - Shot weight in grams(每模的总重量): | R16: Output - Shot weight in grams | Z16: 最大射速 | AA16: Max. Injection Speed | BG16: 回料时间 | BH16: Measure Time | BM16: 模具不能进行射速优化、保压压力测试、保压时间测试，必须做参数可允许度测试，如能执行上述测试，可不做可允许度测试。 | BP16: 开合模动作顺畅无异响 | BQ16: Mold open/close smoothly without abnormal noise | CB16: 行位动作
B17: 注射速度优化 | C17: Optimized Injection Speed | E17: 3.模具工程师必须在收到此报告的3个工作日之内给出对所反映问题点的改善措施，并书面回复给品质工程师。 | F17: 3. The tooling engineer must submit the improvement actions within 3 working days after receiving this report. | H17: 运水通畅不漏水 | K17: 3. 行位底部有顶针，合模前顶针板必须完全复位 | L17: Notation Three | N17: 模具最小厚度 | O17: Min Mold Thickness | Q17: Output - Residence Time (in minutes)停留時间: | R17: Output - Residence Time (in minutes) | Z17: 最大射压 | AA17: Max. Injection pressure | BP17: 顶出/复位顺畅无异响 | BQ17: Ejection/Retraction smoothly without abnormal noise | CB17: 油唧动作
B18: 走水平衡分析 | C18: Short Shot Balance | E18: 4. 模具工程师改善好模具问题点之后，必须提前通知品质工程师进行现场验证，根据模具工程师提出的改善措施进行跟踪确认。 | F18: 4. All mold open issues must be tested and closed on site. | H18: 浇口省滑不拖胶粉 | K18: 4. 此模有嵌件，需注意嵌件的摆放位置是否正确。 | L18: Notation Four | N18: 模板最大开距 | O18: Min Template Interval | Z18: 增压比 | AA18: Intensification Ratio | BP18: 行位动作顺畅无异响 | BQ18: Slider moving smoothly without abnormal noise | CB18: 热咀封针
B19: 压力损失报告 | C19: Pressure Loss Report | E19: 制作/Prepared by: | F19: Prepared by: | H19: 可换镶件更换方便 | K19: 5. 此模采用了二次顶出机构。 | L19: Notation Five | N19: 模板最小开距 | O19: Max Template Interval | Z19: 每啤总量 | AA19: Weight per shot | BP19: 油唧动作顺畅无异响 | BQ19: Hydraulic moving smoothly without abnormal noise
B20: 保压压力测试报告 | C20: Holding Pressure Test Report | E20: 日期/Date: | F20: Date: | H20: 氮化/涂层工件已处理OK | K20: 6. 此模有加速顶出机构 | L20: Notation Six | N20: 顶出行程 | O20: Ejection Stroke | Z20: 产品重量 | AA20: Product weight | BP20: 热咀封针/热流道无不良 | BQ20: Valve stem/HRS without defects | CB20: 产品取件
B21: 保压时间优化 | C21: Optimized Holding Time Report | E21: 审核/Aprroved by: | F21: Aprroved by: | H21: 斜顶不铲胶 | K21: 7. 有换款。 | L21: Notation Seven | N21: 拉杆间距 | O21: Pull Rod Interval | Z21: 切换位置重量 | AA21: Weight of transfer | BP21: 平面顶针能转动 | BQ21: Flat EJ can rotate
B22: 冷却时间优化 | C22: Optimized Cooling Time Report | E22: 日期/Date: | F22: Date: | H22: 行位有限位装置 | K22: 换款动作： | L22: Change Action | N22: 拉杆接头 | O22: Pull Rod Size | Z22: 试模类型 | AA22: Trial type | BP22: 产品/水口取件符合要求 | BQ22: Product/Runner's pick-up meets the requirements
B23: 锁模力优化报告 | C23: Optimized Clamp Force Report | H23: 水口出模顺畅不粘模 | K23: 模具排位图 | L23: Mold Ranking Chart | Z23: 科学试模 | AA23: Scientific Molding | BP23: 第三部分:制作工艺 | BQ23: Part III:Mold Craftsmanship
B24: 周期时间优化报告 | C24: Optimized Cycle Time Report | H24: 产品出模顺畅不粘模 | K24: 模具重量 | L24: Mold Weight | Z24: 正常啤塑胶（满足生产时） | AA24: Fit to produce | BP24: 运水通畅不漏水 | BQ24: No water leakage and no blockage
B25: 模具问题点履历表 | C25: Mold Open Issue Record | H25: 顶针印无披锋/不凸起 | Z25: 非正常啤塑（啤样板时） | AA25: Only fit to mold trial | BP25: 浇口省滑不拖胶粉 | BQ25: Good polishing on the gate and no scrap chips
B26: 可容许度测试报告 | C26: Acceptability Test Report | H26: 第三部分: 设备接驳和操作性能 | Z26: 温度控制 | AA26: Control Temperature | BP26: 可换镶件更换方便 | BQ26: Exchangeable inserts are easy to replace
H27: 喉咀接驳方便无阻碍 | Z27: 料筒温度控制 | AA27: Temp. of hopper(℃) | BP27: 氮化/涂层工件已处理OK | BQ27: Nitriding/Coating has been done
H28: 电源接驳安全无阻碍 | Z28: 单位 | AA28: Unit | BP28: 斜顶不铲胶 | BQ28: top surface of lifter has no scratches with sample
H29: 水油气接驳方便无阻碍 | Z29: 料筒温度段数 | AA29: Hopper number | BP29: 行位有限位装置 | BQ29: Slider retainer/stopper block existed
H30: 咭掣接驳方便无阻碍 | Z30: 加热区域 | AA30: Heating zone | BP30: 水口出模顺畅不粘模 | BQ30: Demolding the runner easily and no sticking
H31: 模具与啤机无溢胶 | Z31: 温度值 | AA31: Temperature | BP31: 产品出模顺畅不粘模 | BQ31: Demolding the part easily and no sticking
H32: 模具吊装上落模安全方便 | Z32: 热流道温度控制 | AA32: Temp. of hot runner(℃) | BP32: 产品字唛做妥符合要求 | BQ32: Engrave is correct
H33: 各保护咭掣能正常使用 | Z33: 热流道数量 | AA33: Hot runner number | BP33: 顶针印无披锋/不凸起 | BQ33: enjector mark is flat and no flash
H34: 第四部分: 注塑工艺 | Z34: 热流道编号 | AA34: Hot runner NO. | BP34: 第四部分:设备接驳和操作性能 | BQ34: Part Ⅳ: Mold Connection
H35: 锁模力符合要求 | Z35: 模温控制 | AA35: Control mold temperature | BP35: 喉咀接驳方便无阻碍 | BQ35: Safe and good connection on cooling
H36: 注塑周期符合要求 | Z36: 加热方式： | AA36: Heating way | BP36: 电源接驳安全无阻碍 | BQ36: Safe and good connection on power
H37: 注塑工艺窗宽，工艺条件仍可上下浮动范围±10% | Z37: 水温 | AA37: Water | BP37: 水油气接驳方便无阻碍 | BQ37: Convenient water/oil/gas connection
H38: 2腔及以上走胶平衡测试 | Z38: 油温 | AA38: Oil | BP38: 咭掣接驳方便无阻碍 | BQ38: Safe and good connection on limit switches
... H52: 1、表中的第一部分到第五部分的内容需要由试模员检查完成并记录签名确认； 2、表中的第六部分到第七部分的内容需要由制作工程师检查完成并记录签名确认； 3、所有检查NG的项目，由制作工程师在“备注”栏做NG内容描述以及决定NG内容的处理方法，并将其处理方式的代码填于“处理方法及项目号”栏中；NG项处理方法：A、修模/改模 B、走模前完成 C、让步接收； 4、若用修模/改模处理方法，需将<修模/改模工作单>中对应的项目号填写于“处理方法及项目号”栏； 5、模具动作检查时需按快、中、慢三种速度进行设定,一旦发生模具结构/动作问题,制作工程师应按要求组织相关人员检讨/改善； 6、所有项目检查完成后由制作工程师交制作经理审核后存档。 | Z52: 组9: | AA52: Zone9: | BP52: 产品外观无缺陷 | BQ52: No defects in product appearance
Z53: 组10: | AA53: Zone10: | BP53: 产品结构与3D相符 | BQ53: Sample conforms to 3D model
...

Sheet 试模总结报告
A1: Back
C2: =IF(目录!G2="中文",对照!E2,IF(目录!G2="English",对照!F2,对照!E2)) -> 模具验证测试总结报告
C4: =IF(目录!G2="中文",对照!E3,IF(目录!G2="English",对照!F3,对照!E3)) -> 模号 Mold Number | F4: =IF(目录!G2="中文",对照!E4,IF(目录!G2="English",对照!F4,对照!E4)) -> 测试时间 Test Date | H4: =IF(目录!G2="中文",对照!E5,IF(目录!G2="English",对照!F5,对照!E5)) -> 模具工程师 Molding Engineer | J4: =IF(目录!G2="中文",对照!E6,IF(目录!G2="English",对照!F6,对照!E6)) -> 项目工程师 Project Engineer
C6: =IF(目录!G2="中文",对照!E7,IF(目录!G2="English",对照!F7,对照!E7)) -> A. 模具问题点描述/Mold issue:
C13: =IF(目录!G2="中文",对照!E8,IF(目录!G2="English",对照!F8,对照!E8)) -> 模具判定: Result of mold:
C14: =IF(目录!G2="中文",对照!E9,IF(目录!G2="English",对照!F9,对照!E9)) -> B. 产品问题点描述/Part issue：
C21: =IF(目录!G2="中文",对照!E10,IF(目录!G2="English",对照!F10,对照!E10)) -> 塑胶产品判定: Result of part:
C22: =IF(目录!G2="中文",对照!E11,IF(目录!G2="English",对照!F11,对照!E11)) -> C. 改善措施/Corrective or Improvement action
C29: =IF(目录!G2="中文",对照!E13,IF(目录!G2="English",对照!F13,对照!E13)) -> D.模具验证测试结果最终确认/Final Result：
C32: 注/Note: | D32: =IF(目录!G2="中文",对照!E15,IF(目录!G2="English",对照!F15,对照!E15)) -> 1. 模具验证测试结果判定合格标准为流道浇口在修模中不需要加大，模具验证测试完成；反之就可判定不合格。
D33: =IF(目录!G2="中文",对照!E16,IF(目录!G2="English",对照!F16,对照!E16)) -> 2.品质工程师发出此报告后，项目工程师若对表格内容有疑义的，项目工程师需及时给予书面回复。
D34: =IF(目录!G2="中文",对照!E17,IF(目录!G2="English",对照!F17,对照!E17)) -> 3.模具工程师必须在收到此报告的3个工作日之内给出对所反映问题点的改善措施，并书面回复给品质工程师。
D35: =IF(目录!G2="中文",对照!E18,IF(目录!G2="English",对照!F18,对照!E18)) -> 4. 模具工程师改善好模具问题点之后，必须提前通知品质工程师进行现场验证，根据模具工程师提出的改善措施进行跟踪确认。
C37: =IF(目录!G2="中文",对照!E19,IF(目录!G2="English",对照!F19,对照!E19)) -> 制作/Prepared by: | F37: =IF(目录!G2="中文",对照!E20,IF(目录!G2="English",对照!F20,对照!E20)) -> 日期/Date: | H37: =IF(目录!G2="中文",对照!E21,IF(目录!G2="English",对照!F21,对照!E21)) -> 审核/Aprroved by: | J37: =IF(目录!G2="中文",对照!E22,IF(目录!G2="English",对照!F22,对照!E22)) -> 日期/Date:
K38: 保存期限：走模后2年

Sheet 模具表现评估
A1: Back
A2: =IF(目录!G2="中文",对照!BP2,IF(目录!G2="English",对照!BQ2,对照!BP2)) -> 模具表现评估
A3: =IF(目录!G2="中文",对照!BP3,IF(目录!G2="English",对照!BQ3,对照!BP3)) -> 模 号: | C3: =IF(目录!G2="中文",对照!BP4,IF(目录!G2="English",对照!BQ4,对照!BP4)) -> 制作工程师: | F3: =IF(目录!G2="中文",对照!BP5,IF(目录!G2="English",对照!BQ5,对照!BP5)) -> 审 核: | I3: =IF(目录!G2="中文",对照!AF11,IF(目录!G2="English",对照!AG11,对照!AF11)) -> 结果
A4: =IF(目录!G2="中文",对照!BP6,IF(目录!G2="English",对照!BQ6,对照!BP6)) -> 试模员: | C4: =IF(目录!G2="中文",对照!BP7,IF(目录!G2="English",对照!BQ7,对照!BP7)) -> 试模次数 | F4: =IF(目录!G2="中文",对照!BP8,IF(目录!G2="English",对照!BQ8,对照!BP8)) -> 试模日期:
A5: =IF(目录!G2="中文",对照!BP9,IF(目录!G2="English",对照!BQ9,对照!BP9)) -> 检查项目 | B5: =IF(目录!G2="中文",对照!BP10,IF(目录!G2="English",对照!BQ10,对照!BP10)) -> 检查细则 | G5: =IF(目录!G2="中文",对照!BJ6,IF(目录!G2="English",对照!BK6,对照!BJ6)) -> 备注 | I5: =IF(目录!G2="中文",对照!BP14,IF(目录!G2="English",对照!BQ14,对照!BP14)) -> 处理方法 | J5: =IF(目录!G2="中文",对照!BP13,IF(目录!G2="English",对照!BQ13,对照!BP13)) -> 签名确认
D6: OK | E6: NG | F6: NA
A7: =IF(目录!G2="中文",对照!BP61,IF(目录!G2="English",对照!BQ61,对照!BP61)) -> 第一部分：模具结构信息 | B7: =IF(目录!G2="中文",对照!BP62,IF(目录!G2="English",对照!BQ62,对照!BP62)) -> 确认模具尺寸、开模行程、熔胶量、定位环规格等与注塑机匹配
B8: =IF(目录!G2="中文",对照!BP63,IF(目录!G2="English",对照!BQ63,对照!BP63)) -> 确认模具特殊注意事项
B9: =IF(目录!G2="中文",对照!BP64,IF(目录!G2="English",对照!BQ64,对照!BP64)) -> 确认水路连接方式、水管规格是否合理
B10: =IF(目录!G2="中文",对照!BP65,IF(目录!G2="English",对照!BQ65,对照!BP65)) -> 需要热流道或加热棒
B11: =IF(目录!G2="中文",对照!BP66,IF(目录!G2="English",对照!BQ66,对照!BP66)) -> 温控箱准备ok
B12: =IF(目录!G2="中文",对照!BP67,IF(目录!G2="English",对照!BQ67,对照!BP67)) -> 模具取数、模穴号位置合理
B13: =IF(目录!G2="中文",对照!BP68,IF(目录!G2="English",对照!BQ68,对照!BP68)) -> 确认材料规格型、物性表
B14: =IF(目录!G2="中文",对照!BP69,IF(目录!G2="English",对照!BQ69,对照!BP69)) -> 需要五金件
B15: =IF(目录!G2="中文",对照!BP70,IF(目录!G2="English",对照!BQ70,对照!BP70)) -> 如需要，确认五金件是否准备好
B16: =IF(目录!G2="中文",对照!BP71,IF(目录!G2="English",对照!BQ71,对照!BP71)) -> 是否封针
A17: =IF(目录!G2="中文",对照!BP15,IF(目录!G2="English",对照!BQ15,对照!BP15)) -> 第二部分:模具动作和功能 | B17: =IF(目录!G2="中文",对照!BP16,IF(目录!G2="English",对照!BQ16,对照!BP16)) -> 开合模动作顺畅无异响
B18: =IF(目录!G2="中文",对照!BP17,IF(目录!G2="English",对照!BQ17,对照!BP17)) -> 顶出/复位顺畅无异响 | C18: 顶出/复位
B19: =IF(目录!G2="中文",对照!BP18,IF(目录!G2="English",对照!BQ18,对照!BP18)) -> 行位动作顺畅无异响 | C19: 行位动作
B20: =IF(目录!G2="中文",对照!BP19,IF(目录!G2="English",对照!BQ19,对照!BP19)) -> 油唧动作顺畅无异响 | C20: 油唧动作
B21: =IF(目录!G2="中文",对照!BP20,IF(目录!G2="English",对照!BQ20,对照!BP20)) -> 热咀封针/热流道无不良 | C21: 热咀封针
B22: =IF(目录!G2="中文",对照!BP21,IF(目录!G2="English",对照!BQ21,对照!BP21)) -> 平面顶针能转动
B23: =IF(目录!G2="中文",对照!BP22,IF(目录!G2="English",对照!BQ22,对照!BP22)) -> 产品/水口取件符合要求 | C23: 产品取件
A24: =IF(目录!G2="中文",对照!BP23,IF(目录!G2="English",对照!BQ23,对照!BP23)) -> 第三部分:制作工艺 | B24: =IF(目录!G2="中文",对照!BP24,IF(目录!G2="English",对照!BQ24,对照!BP24)) -> 运水通畅不漏水
B25: =IF(目录!G2="中文",对照!BP25,IF(目录!G2="English",对照!BQ25,对照!BP25)) -> 浇口省滑不拖胶粉
B26: =IF(目录!G2="中文",对照!BP26,IF(目录!G2="English",对照!BQ26,对照!BP26)) -> 可换镶件更换方便
B27: =IF(目录!G2="中文",对照!BP27,IF(目录!G2="English",对照!BQ27,对照!BP27)) -> 氮化/涂层工件已处理OK
B28: =IF(目录!G2="中文",对照!BP28,IF(目录!G2="English",对照!BQ28,对照!BP28)) -> 斜顶不铲胶
B29: =IF(目录!G2="中文",对照!BP29,IF(目录!G2="English",对照!BQ29,对照!BP29)) -> 行位有限位装置
B30: =IF(目录!G2="中文",对照!BP30,IF(目录!G2="English",对照!BQ30,对照!BP30)) -> 水口出模顺畅不粘模
B31: =IF(目录!G2="中文",对照!BP31,IF(目录!G2="English",对照!BQ31,对照!BP31)) -> 产品出模顺畅不粘模
B32: =IF(目录!G2="中文",对照!BP32,IF(目录!G2="English",对照!BQ32,对照!BP32)) -> 产品字唛做妥符合要求
B33: =IF(目录!G2="中文",对照!BP33,IF(目录!G2="English",对照!BQ33,对照!BP33)) -> 顶针印无披锋/不凸起
A34: =IF(目录!G2="中文",对照!BP34,IF(目录!G2="English",对照!BQ34,对照!BP34)) -> 第四部分:设备接驳和操作性能 | B34: =IF(目录!G2="中文",对照!BP35,IF(目录!G2="English",对照!BQ35,对照!BP35)) -> 喉咀接驳方便无阻碍
B35: =IF(目录!G2="中文",对照!BP36,IF(目录!G2="English",对照!BQ36,对照!BP36)) -> 电源接驳安全无阻碍
B36: =IF(目录!G2="中文",对照!BP37,IF(目录!G2="English",对照!BQ37,对照!BP37)) -> 水油气接驳方便无阻碍
B37: =IF(目录!G2="中文",对照!BP38,IF(目录!G2="English",对照!BQ38,对照!BP38)) -> 咭掣接驳方便无阻碍
B38: =IF(目录!G2="中文",对照!BP39,IF(目录!G2="English",对照!BQ39,对照!BP39)) -> 模具与啤机无溢胶
B39: =IF(目录!G2="中文",对照!BP40,IF(目录!G2="English",对照!BQ40,对照!BP40)) -> 模具吊装上落模安全方便
B40: =IF(目录!G2="中文",对照!BP41,IF(目录!G2="English",对照!BQ41,对照!BP41)) -> 各保护咭掣能正常使用
...

Sheet 试模参数记录表
A1: Back
A2: =IF(目录!G2="中文",对照!Z2,IF(目录!G2="English",对照!AA2,对照!Z2)) -> 试模参数记录表
A3: =IF(目录!G2="中文",对照!Z3,IF(目录!G2="English",对照!AA3,对照!Z3)) -> 基本信息
A4: 模具编号 | U4: 试模次数 | AO4: 机器型号
A5: 型腔数 | Q5: 腔 | U5: 客户
A6: 主射台
A7: 胶料类别 | Q7: s | U7: 颜色 | AO7: 干燥方法
A8: 干燥温度 | Q8: ℃ | U8: 干燥时间 | AK8: h
A9: 喷嘴孔直径 | Q9: mm | U9: 螺杆直径 | AK9: mm | AO9: 螺杆压缩比
A10: 最大可设定注射压力 | Y10: Mpa | AE10: 最大可设定注射速度 | BC10: mm/s
A11: 切换位置重量 | Q11: g | U11: 制品总重量 | AK11: g | AO11: 制品单件重量 | BE11: g
A12: =IF(目录!G2="中文",对照!Z22,IF(目录!G2="English",对照!AA22,对照!Z22)) -> 试模类型 | I12: 科学试模 | W12: 正常啤塑胶（满足生产时） | AO12: 非正常啤塑（啤样板时）
A13: =IF(目录!G2="中文",对照!Z26,IF(目录!G2="English",对照!AA26,对照!Z26)) -> 温度控制
A14: =IF(目录!G2="中文",对照!Z32,IF(目录!G2="English",对照!AA32,对照!Z32)) -> 热流道温度控制 | P14: =IF(目录!G2="中文",对照!Z28,IF(目录!G2="English",对照!AA28,对照!Z28)) -> 单位 | U14: ℃ | Z14: =IF(目录!G2="中文",对照!Z33,IF(目录!G2="English",对照!AA33,对照!Z33)) -> 热流道数量
A15: 热流道编号 | K15: 1 | P15: 2 | U15: 3 | Z15: 4 | AE15: 5 | AJ15: 6 | AO15: 7 | AT15: 8 | AY15: 9 | BD15: 10
A16: 温度值 | K16: #HRT1 | P16: #HRT2 | U16: #HRT3 | Z16: #HRT4 | AE16: #HRT5 | AJ16: #HRT6 | AO16: #HRT7 | AT16: #HRT8 | AY16: #HRT9 | BD16: #HRT10
A17: 11 | F17: 12 | K17: 13 | P17: 14 | U17: 15 | Z17: 16 | AE17: 17 | AJ17: 18 | AO17: 19 | AT17: 20 | AY17: 21 | BD17: 22
A18: #HRT11 | F18: #HRT12 | K18: #HRT13 | P18: #HRT14 | U18: #HRT15 | Z18: #HRT16 | AE18: #HRT17 | AJ18: #HRT18 | AO18: #HRT19 | AT18: #HRT20 | AY18: #HRT21 | BD18: #HRT22
A19: 23 | F19: 24 | K19: 25 | P19: 26 | U19: 27 | Z19: 28 | AE19: 29 | AJ19: 30 | AO19: 31 | AT19: 32 | AY19: 33 | BD19: 34
A20: #HRT23 | F20: #HRT24 | K20: #HRT25 | P20: #HRT26 | U20: #HRT27 | Z20: #HRT28 | AE20: #HRT29 | AJ20: #HRT30 | AO20: #HRT31 | AT20: #HRT32 | AY20: #HRT33 | BD20: #HRT34
A21: 35 | F21: 36 | K21: 37 | P21: 38 | U21: 39 | Z21: 40 | AE21: 41 | AJ21: 42 | AO21: 43 | AT21: 44 | AY21: 45 | BD21: 46
A22: #HRT35 | F22: #HRT36 | K22: #HRT37 | P22: #HRT38 | U22: #HRT39 | Z22: #HRT40 | AE22: #HRT41 | AJ22: #HRT42 | AO22: #HRT43 | AT22: #HRT44 | AY22: #HRT45 | BD22: #HRT46
A23: 47 | F23: 48 | K23: 49 | P23: 50 | U23: 51 | Z23: 52 | AE23: 53 | AJ23: 54 | AO23: 55 | AT23: 56 | AY23: 57 | BD23: 58
A24: #HRT47 | F24: #HRT48 | K24: #HRT49 | P24: #HRT50 | U24: #HRT51 | Z24: #HRT52 | AE24: #HRT53 | AJ24: #HRT54 | AO24: #HRT55 | AT24: #HRT56 | AY24: #HRT57 | BD24: #HRT58
A25: 59 | F25: 60 | K25: 61 | P25: 62 | U25: 63 | Z25: 64 | AE25: 65 | AJ25: 66 | AO25: 67 | AT25: 68 | AY25: 69 | BD25: 70
A26: #HRT59 | F26: #HRT60 | K26: #HRT61 | P26: #HRT62 | U26: #HRT63 | Z26: #HRT64 | AE26: #HRT65 | AJ26: #HRT66 | AO26: #HRT67 | AT26: #HRT68 | AY26: #HRT69 | BD26: #HRT70
A27: 71 | F27: 72 | K27: 73 | P27: 74 | U27: 75 | Z27: 76 | AE27: 77 | AJ27: 78 | AO27: 79 | AT27: 80 | AY27: 81 | BD27: 82
A28: #HRT71 | F28: #HRT72 | K28: #HRT73 | P28: #HRT74 | U28: #HRT75 | Z28: #HRT76 | AE28: #HRT77 | AJ28: #HRT78 | AO28: #HRT79 | AT28: #HRT80 | AY28: #HRT81 | BD28: #HRT82
A29: 83 | F29: 84 | K29: 85 | P29: 86 | U29: 87 | Z29: 88 | AE29: 89 | AJ29: 90 | AO29: 91 | AT29: 92 | AY29: 93 | BD29: 94
A30: #HRT83 | F30: #HRT84 | K30: #HRT85 | P30: #HRT86 | U30: #HRT87 | Z30: #HRT88 | AE30: #HRT89 | AJ30: #HRT90 | AO30: #HRT91 | AT30: #HRT92 | AY30: #HRT93 | BD30: #HRT94
A31: 95 | F31: 96 | K31: 97 | P31: 98 | U31: 99 | Z31: 100 | AE31: 101 | AJ31: 102 | AO31: 103 | AT31: 104 | AY31: 105 | BD31: 106
A32: #HRT95 | F32: #HRT96 | K32: #HRT97 | P32: #HRT98 | U32: #HRT99 | Z32: #HRT100 | AE32: #HRT101 | AJ32: #HRT102 | AO32: #HRT103 | AT32: #HRT104 | AY32: #HRT105 | BD32: #HRT106
A33: =IF(目录!G2="中文",对照!Z35,IF(目录!G2="English",对照!AA35,对照!Z35)) -> 模温控制
A34: =IF(目录!G2="中文",对照!Z36,IF(目录!G2="English",对照!AA36,对照!Z36)) -> 加热方式： | P34: =IF(目录!G2="中文",对照!Z28,IF(目录!G2="English",对照!AA28,对照!Z28)) -> 单位 | U34: ℃
A36: =IF(目录!G2="中文",对照!Z37,IF(目录!G2="English",对照!AA37,对照!Z37)) -> 水温 | AD36: =IF(目录!G2="中文",对照!Z40,IF(目录!G2="English",对照!AA40,对照!Z40)) -> 1.实测 | AK36: ℃ | AV36: =IF(目录!G2="中文",对照!Z40,IF(目录!G2="English",对照!AA40,对照!Z40)) -> 1.实测 | BC36: ℃
A38: =IF(目录!G2="中文",对照!Z38,IF(目录!G2="English",对照!AA38,对照!Z38)) -> 油温 | AD38: =IF(目录!G2="中文",对照!Z41,IF(目录!G2="English",对照!AA41,对照!Z41)) -> 2.实测 | AK38: ℃ | AV38: =IF(目录!G2="中文",对照!Z41,IF(目录!G2="English",对照!AA41,对照!Z41)) -> 2.实测 | BC38: ℃
A40: =IF(目录!G2="中文",对照!Z39,IF(目录!G2="English",对照!AA39,对照!Z39)) -> 电加热 | AD40: =IF(目录!G2="中文",对照!Z42,IF(目录!G2="English",对照!AA42,对照!Z42)) -> 3.实测 | AK40: ℃ | AV40: =IF(目录!G2="中文",对照!Z42,IF(目录!G2="English",对照!AA42,对照!Z42)) -> 3.实测 | BC40: ℃
A42: 模具运水图
A43: 简图 | E43: 后模 | BE43: 前模
A49: 具体接法 | E49: 运水回路组数 | U49: 组
...

Sheet 试模参数记录表-副射台
A1: Back
A2: =IF(目录!G2="中文",对照!Z2,IF(目录!G2="English",对照!AA2,对照!Z2)) -> 试模参数记录表
A3: =IF(目录!G2="中文",对照!Z3,IF(目录!G2="English",对照!AA3,对照!Z3)) -> 基本信息
A4: 模具编号 | U4: 试模次数 | AO4: 机器型号
A5: 型腔数 | Q5: 腔 | U5: 客户
A6: 副射台
A7: 胶料类别 | Q7: s | U7: 颜色 | AO7: 干燥方法
A8: 干燥温度 | Q8: ℃ | U8: 干燥时间 | AK8: h
A9: 喷嘴孔直径 | Q9: mm | U9: 螺杆直径 | AK9: mm | AO9: 螺杆压缩比
A10: 最大可设定注射压力 | Y10: Mpa | AE10: 最大可设定注射速度 | BC10: mm/s
A11: 切换位置重量 | Q11: g | U11: 制品总重量 | AK11: g | AO11: 制品单件重量 | BE11: g
A12: =IF(目录!G2="中文",对照!Z22,IF(目录!G2="English",对照!AA22,对照!Z22)) -> 试模类型 | I12: 科学试模 | W12: 正常啤塑胶（满足生产时） | AO12: 非正常啤塑（啤样板时）
A13: =IF(目录!G2="中文",对照!Z26,IF(目录!G2="English",对照!AA26,对照!Z26)) -> 温度控制
A14: =IF(目录!G2="中文",对照!Z32,IF(目录!G2="English",对照!AA32,对照!Z32)) -> 热流道温度控制 | P14: =IF(目录!G2="中文",对照!Z28,IF(目录!G2="English",对照!AA28,对照!Z28)) -> 单位 | U14: ℃ | Z14: =IF(目录!G2="中文",对照!Z33,IF(目录!G2="English",对照!AA33,对照!Z33)) -> 热流道数量
A15: 热流道编号 | K15: 1 | P15: 2 | U15: 3 | Z15: 4 | AE15: 5 | AJ15: 6 | AO15: 7 | AT15: 8 | AY15: 9 | BD15: 10
A16: 温度值 | K16: #HRT1 | P16: #HRT2 | U16: #HRT3 | Z16: #HRT4 | AE16: #HRT5 | AJ16: #HRT6 | AO16: #HRT7 | AT16: #HRT8 | AY16: #HRT9 | BD16: #HRT10
A17: 11 | F17: 12 | K17: 13 | P17: 14 | U17: 15 | Z17: 16 | AE17: 17 | AJ17: 18 | AO17: 19 | AT17: 20 | AY17: 21 | BD17: 22
A18: #HRT11 | F18: #HRT12 | K18: #HRT13 | P18: #HRT14 | U18: #HRT15 | Z18: #HRT16 | AE18: #HRT17 | AJ18: #HRT18 | AO18: #HRT19 | AT18: #HRT20 | AY18: #HRT21 | BD18: #HRT22
A19: 23 | F19: 24 | K19: 25 | P19: 26 | U19: 27 | Z19: 28 | AE19: 29 | AJ19: 30 | AO19: 31 | AT19: 32 | AY19: 33 | BD19: 34
A20: #HRT23 | F20: #HRT24 | K20: #HRT25 | P20: #HRT26 | U20: #HRT27 | Z20: #HRT28 | AE20: #HRT29 | AJ20: #HRT30 | AO20: #HRT31 | AT20: #HRT32 | AY20: #HRT33 | BD20: #HRT34
A21: 35 | F21: 36 | K21: 37 | P21: 38 | U21: 39 | Z21: 40 | AE21: 41 | AJ21: 42 | AO21: 43 | AT21: 44 | AY21: 45 | BD21: 46
A22: #HRT35 | F22: #HRT36 | K22: #HRT37 | P22: #HRT38 | U22: #HRT39 | Z22: #HRT40 | AE22: #HRT41 | AJ22: #HRT42 | AO22: #HRT43 | AT22: #HRT44 | AY22: #HRT45 | BD22: #HRT46
A23: 47 | F23: 48 | K23: 49 | P23: 50 | U23: 51 | Z23: 52 | AE23: 53 | AJ23: 54 | AO23: 55 | AT23: 56 | AY23: 57 | BD23: 58
A24: #HRT47 | F24: #HRT48 | K24: #HRT49 | P24: #HRT50 | U24: #HRT51 | Z24: #HRT52 | AE24: #HRT53 | AJ24: #HRT54 | AO24: #HRT55 | AT24: #HRT56 | AY24: #HRT57 | BD24: #HRT58
A25: 59 | F25: 60 | K25: 61 | P25: 62 | U25: 63 | Z25: 64 | AE25: 65 | AJ25: 66 | AO25: 67 | AT25: 68 | AY25: 69 | BD25: 70
A26: #HRT59 | F26: #HRT60 | K26: #HRT61 | P26: #HRT62 | U26: #HRT63 | Z26: #HRT64 | AE26: #HRT65 | AJ26: #HRT66 | AO26: #HRT67 | AT26: #HRT68 | AY26: #HRT69 | BD26: #HRT70
A27: 71 | F27: 72 | K27: 73 | P27: 74 | U27: 75 | Z27: 76 | AE27: 77 | AJ27: 78 | AO27: 79 | AT27: 80 | AY27: 81 | BD27: 82
A28: #HRT71 | F28: #HRT72 | K28: #HRT73 | P28: #HRT74 | U28: #HRT75 | Z28: #HRT76 | AE28: #HRT77 | AJ28: #HRT78 | AO28: #HRT79 | AT28: #HRT80 | AY28: #HRT81 | BD28: #HRT82
A29: 83 | F29: 84 | K29: 85 | P29: 86 | U29: 87 | Z29: 88 | AE29: 89 | AJ29: 90 | AO29: 91 | AT29: 92 | AY29: 93 | BD29: 94
A30: #HRT83 | F30: #HRT84 | K30: #HRT85 | P30: #HRT86 | U30: #HRT87 | Z30: #HRT88 | AE30: #HRT89 | AJ30: #HRT90 | AO30: #HRT91 | AT30: #HRT92 | AY30: #HRT93 | BD30: #HRT94
A31: 95 | F31: 96 | K31: 97 | P31: 98 | U31: 99 | Z31: 100 | AE31: 101 | AJ31: 102 | AO31: 103 | AT31: 104 | AY31: 105 | BD31: 106
A32: #HRT95 | F32: #HRT96 | K32: #HRT97 | P32: #HRT98 | U32: #HRT99 | Z32: #HRT100 | AE32: #HRT101 | AJ32: #HRT102 | AO32: #HRT103 | AT32: #HRT104 | AY32: #HRT105 | BD32: #HRT106
A33: =IF(目录!G2="中文",对照!Z35,IF(目录!G2="English",对照!AA35,对照!Z35)) -> 模温控制
A34: =IF(目录!G2="中文",对照!Z36,IF(目录!G2="English",对照!AA36,对照!Z36)) -> 加热方式： | P34: =IF(目录!G2="中文",对照!Z28,IF(目录!G2="English",对照!AA28,对照!Z28)) -> 单位 | U34: ℃
A36: =IF(目录!G2="中文",对照!Z37,IF(目录!G2="English",对照!AA37,对照!Z37)) -> 水温 | AD36: =IF(目录!G2="中文",对照!Z40,IF(目录!G2="English",对照!AA40,对照!Z40)) -> 1.实测 | AK36: ℃ | AV36: =IF(目录!G2="中文",对照!Z40,IF(目录!G2="English",对照!AA40,对照!Z40)) -> 1.实测 | BC36: ℃
A38: =IF(目录!G2="中文",对照!Z38,IF(目录!G2="English",对照!AA38,对照!Z38)) -> 油温 | AD38: =IF(目录!G2="中文",对照!Z41,IF(目录!G2="English",对照!AA41,对照!Z41)) -> 2.实测 | AK38: ℃ | AV38: =IF(目录!G2="中文",对照!Z41,IF(目录!G2="English",对照!AA41,对照!Z41)) -> 2.实测 | BC38: ℃
A40: =IF(目录!G2="中文",对照!Z39,IF(目录!G2="English",对照!AA39,对照!Z39)) -> 电加热 | AD40: =IF(目录!G2="中文",对照!Z42,IF(目录!G2="English",对照!AA42,对照!Z42)) -> 3.实测 | AK40: ℃ | AV40: =IF(目录!G2="中文",对照!Z42,IF(目录!G2="English",对照!AA42,对照!Z42)) -> 3.实测 | BC40: ℃
A42: 模具运水图
A43: 简图 | E43: 后模 | BE43: 前模
A49: 具体接法 | E49: 运水回路组数 | U49: 组
...

Sheet 模具问题点履历
A1: Back
A2: =IF(目录!G2="中文",对照!BJ2,IF(目录!G2="English",对照!BK2,对照!BJ2)) -> 模具问题点履历表
A3: =IF(目录!G2="中文",对照!Z4,IF(目录!G2="English",对照!AA4,对照!Z4)) -> 模号 | B3: =IF(目录!G2="中文",对照!Z12,IF(目录!G2="English",对照!AA12,对照!Z12)) -> 试模次数 | C3: =IF(目录!G2="中文",对照!Z122,IF(目录!G2="English",对照!AA122,对照!Z122)) -> 日期: | D3: =IF(目录!G2="中文",对照!BJ3,IF(目录!G2="English",对照!BK3,对照!BJ3)) -> 问题点 | E3: =IF(目录!G2="中文",对照!BJ4,IF(目录!G2="English",对照!BK4,对照!BJ4)) -> 遗留问题点 | F3: =IF(目录!G2="中文",对照!BJ5,IF(目录!G2="English",对照!BK5,对照!BJ5)) -> 新增问题点 | G3: =IF(目录!G2="中文",对照!BJ6,IF(目录!G2="English",对照!BK6,对照!BJ6)) -> 备注 | H3: =IF(目录!G2="中文",对照!BJ7,IF(目录!G2="English",对照!BK7,对照!BJ7)) -> 工程师 | I3: =IF(目录!G2="中文",对照!BJ8,IF(目录!G2="English",对照!BK8,对照!B8)) -> 试模员
I26: 保存期限：1年

Sheet 模具运水状况测试
A1: Back
A2: 模具运水状况测试 Mold Water Flow Condition Test
A3: =IF(目录!G2="中文",对照!AF3,IF(目录!G2="English",对照!AG3,对照!AF3)) -> 组号 Group No. | B3: 定模 | H3: =IF(目录!G2="中文",对照!AF11,IF(目录!G2="English",对照!AG11,对照!AF11)) -> 结果 | I3: =IF(目录!G2="中文",对照!AF3,IF(目录!G2="English",对照!AG3,对照!AF3)) -> 组号 Group No. | J3: 动模 | P3: =IF(目录!G2="中文",对照!AF11,IF(目录!G2="English",对照!AG11,对照!AF11)) -> 结果
B4: =IF(目录!G2="中文",对照!AF5,IF(目录!G2="English",对照!AG5,对照!AF5)) -> 运水直径 （mm） | C4: =IF(目录!G2="中文",对照!AF6,IF(目录!G2="English",对照!AG6,对照!AF6)) -> 水的温度 （℃） | D4: =IF(目录!G2="中文",对照!AF7,IF(目录!G2="English",对照!AG7,对照!AF7)) -> 流量 (g/m) | E4: =IF(目录!G2="中文",对照!AF8,IF(目录!G2="English",对照!AG8,对照!AF8)) -> 水的压力 (kgf/cm²) | F4: =IF(目录!G2="中文",对照!AF9,IF(目录!G2="English",对照!AG9,对照!AF9)) -> 水的粘度系数 (10-6m²/s) | G4: =IF(目录!G2="中文",对照!AF10,IF(目录!G2="English",对照!AG10,对照!AF10)) -> 雷诺系数 | J4: =IF(目录!G2="中文",对照!AF5,IF(目录!G2="English",对照!AG5,对照!AF5)) -> 运水直径 （mm） | K4: =IF(目录!G2="中文",对照!AF6,IF(目录!G2="English",对照!AG6,对照!AF6)) -> 水的温度 （℃） | L4: =IF(目录!G2="中文",对照!AF7,IF(目录!G2="English",对照!AG7,对照!AF7)) -> 流量 (g/m) | M4: =IF(目录!G2="中文",对照!AF8,IF(目录!G2="English",对照!AG8,对照!AF8)) -> 水的压力 (kgf/cm²) | N4: =IF(目录!G2="中文",对照!AF9,IF(目录!G2="English",对照!AG9,对照!AF9)) -> 水的粘度系数 (10-6m²/s) | O4: =IF(目录!G2="中文",对照!AF10,IF(目录!G2="English",对照!AG10,对照!AF10)) -> 雷诺系数
A5: 1# | G5: =IF(ISNUMBER($D5)=TRUE,($D5*4.546*$B5)/(60*$F5*($B5/2)^2*3.14)*10^6," ") | H5: =IF(ISNUMBER($D5)=TRUE,IF($G5>=10000,"OK","NG")," ") | I5: 1# | O5: =IF(ISNUMBER($L5)=TRUE,($L5*4.546*$J5)/(60*$N5*($J5/2)^2*3.14)*10^6," ") | P5: =IF(ISNUMBER($L5)=TRUE,IF($O5>=10000,"OK","NG")," ")
A6: 2# | G6: =IF(ISNUMBER($D6)=TRUE,($D6*4.546*$B6)/(60*$F6*($B6/2)^2*3.14)*10^6," ") | H6: =IF(ISNUMBER($D6)=TRUE,IF($G6>=10000,"OK","NG")," ") | I6: 2# | O6: =IF(ISNUMBER($L6)=TRUE,($L6*4.546*$J6)/(60*$N6*($J6/2)^2*3.14)*10^6," ") | P6: =IF(ISNUMBER($L6)=TRUE,IF($O6>=10000,"OK","NG")," ")
A7: 3# | G7: =IF(ISNUMBER($D7)=TRUE,($D7*4.546*$B7)/(60*$F7*($B7/2)^2*3.14)*10^6," ") | H7: =IF(ISNUMBER($D7)=TRUE,IF($G7>=10000,"OK","NG")," ") | I7: 3# | O7: =IF(ISNUMBER($L7)=TRUE,($L7*4.546*$J7)/(60*$N7*($J7/2)^2*3.14)*10^6," ") | P7: =IF(ISNUMBER($L7)=TRUE,IF($O7>=10000,"OK","NG")," ")
A8: 4# | G8: =IF(ISNUMBER($D8)=TRUE,($D8*4.546*$B8)/(60*$F8*($B8/2)^2*3.14)*10^6," ") | H8: =IF(ISNUMBER($D8)=TRUE,IF($G8>=10000,"OK","NG")," ") | I8: 4# | O8: =IF(ISNUMBER($L8)=TRUE,($L8*4.546*$J8)/(60*$N8*($J8/2)^2*3.14)*10^6," ") | P8: =IF(ISNUMBER($L8)=TRUE,IF($O8>=10000,"OK","NG")," ")
A9: 5# | G9: =IF(ISNUMBER($D9)=TRUE,($D9*4.546*$B9)/(60*$F9*($B9/2)^2*3.14)*10^6," ") | H9: =IF(ISNUMBER($D9)=TRUE,IF($G9>=10000,"OK","NG")," ") | I9: 5# | O9: =IF(ISNUMBER($L9)=TRUE,($L9*4.546*$J9)/(60*$N9*($J9/2)^2*3.14)*10^6," ") | P9: =IF(ISNUMBER($L9)=TRUE,IF($O9>=10000,"OK","NG")," ")
A10: 6# | G10: =IF(ISNUMBER($D10)=TRUE,($D10*4.546*$B10)/(60*$F10*($B10/2)^2*3.14)*10^6," ") | H10: =IF(ISNUMBER($D10)=TRUE,IF($G10>=10000,"OK","NG")," ") | I10: 6# | O10: =IF(ISNUMBER($L10)=TRUE,($L10*4.546*$J10)/(60*$N10*($J10/2)^2*3.14)*10^6," ") | P10: =IF(ISNUMBER($L10)=TRUE,IF($O10>=10000,"OK","NG")," ")
A11: 7# | G11: =IF(ISNUMBER($D11)=TRUE,($D11*4.546*$B11)/(60*$F11*($B11/2)^2*3.14)*10^6," ") | H11: =IF(ISNUMBER($D11)=TRUE,IF($G11>=10000,"OK","NG")," ") | I11: 7# | O11: =IF(ISNUMBER($L11)=TRUE,($L11*4.546*$J11)/(60*$N11*($J11/2)^2*3.14)*10^6," ") | P11: =IF(ISNUMBER($L11)=TRUE,IF($O11>=10000,"OK","NG")," ")
A12: 8# | G12: =IF(ISNUMBER($D12)=TRUE,($D12*4.546*$B12)/(60*$F12*($B12/2)^2*3.14)*10^6," ") | H12: =IF(ISNUMBER($D12)=TRUE,IF($G12>=10000,"OK","NG")," ") | I12: 8# | O12: =IF(ISNUMBER($L12)=TRUE,($L12*4.546*$J12)/(60*$N12*($J12/2)^2*3.14)*10^6," ") | P12: =IF(ISNUMBER($L12)=TRUE,IF($O12>=10000,"OK","NG")," ")
A13: 9# | G13: =IF(ISNUMBER($D13)=TRUE,($D13*4.546*$B13)/(60*$F13*($B13/2)^2*3.14)*10^6," ") | H13: =IF(ISNUMBER($D13)=TRUE,IF($G13>=10000,"OK","NG")," ") | I13: 9# | O13: =IF(ISNUMBER($L13)=TRUE,($L13*4.546*$J13)/(60*$N13*($J13/2)^2*3.14)*10^6," ") | P13: =IF(ISNUMBER($L13)=TRUE,IF($O13>=10000,"OK","NG")," ")
A14: 10# | G14: =IF(ISNUMBER($D14)=TRUE,($D14*4.546*$B14)/(60*$F14*($B14/2)^2*3.14)*10^6," ") | H14: =IF(ISNUMBER($D14)=TRUE,IF($G14>=10000,"OK","NG")," ") | I14: 10# | O14: =IF(ISNUMBER($L14)=TRUE,($L14*4.546*$J14)/(60*$N14*($J14/2)^2*3.14)*10^6," ") | P14: =IF(ISNUMBER($L14)=TRUE,IF($O14>=10000,"OK","NG")," ")
A15: 11# | G15: =IF(ISNUMBER($D15)=TRUE,($D15*4.546*$B15)/(60*$F15*($B15/2)^2*3.14)*10^6," ") | H15: =IF(ISNUMBER($D15)=TRUE,IF($G15>=10000,"OK","NG")," ") | I15: 11# | O15: =IF(ISNUMBER($L15)=TRUE,($L15*4.546*$J15)/(60*$N15*($J15/2)^2*3.14)*10^6," ") | P15: =IF(ISNUMBER($L15)=TRUE,IF($O15>=10000,"OK","NG")," ")
A16: 12# | G16: =IF(ISNUMBER($D16)=TRUE,($D16*4.546*$B16)/(60*$F16*($B16/2)^2*3.14)*10^6," ") | H16: =IF(ISNUMBER($D16)=TRUE,IF($G16>=10000,"OK","NG")," ") | I16: 12# | O16: =IF(ISNUMBER($L16)=TRUE,($L16*4.546*$J16)/(60*$N16*($J16/2)^2*3.14)*10^6," ") | P16: =IF(ISNUMBER($L16)=TRUE,IF($O16>=10000,"OK","NG")," ")
... A28: 24# | G28: =IF(ISNUMBER($D28)=TRUE,($D28*4.546*$B28)/(60*$F28*($B28/2)^2*3.14)*10^6," ") | H28: =IF(ISNUMBER($D28)=TRUE,IF($G28>=10000,"OK","NG")," ") | I28: 24# | O28: =IF(ISNUMBER($L28)=TRUE,($L28*4.546*$J28)/(60*$N28*($J28/2)^2*3.14)*10^6," ") | P28: =IF(ISNUMBER($L28)=TRUE,IF($O28>=10000,"OK","NG")," ")
A29: 25# | I29: 25#
A30: 26# | I30: 26#
A31: 27# | I31: 27#
A32: 28# | I32: 28#
A33: 29# | I33: 29#
A34: 30# | I34: 30#
A35: 31# | I35: 31#
A36: 32# | I36: 32#
A37: 33# | I37: 33#
A38: 34# | I38: 34#
A39: 35# | I39: 35#
A40: 36# | I40: 36#
... A54: 50# | I54: 50#
A56: 备注 Remark
P66: 保存期限：走模后2年

Sheet 模具冷却均匀性测试
A1: Back
A2: =IF(目录!G2="中文",对照!AI2,IF(目录!G2="English",对照!AJ2,对照!AI2)) -> 模具冷却均匀性测试 Water Circuit Temperature Report
B5: =IF(目录!G2="中文",对照!AI3,IF(目录!G2="English",对照!AJ3,对照!AI3)) -> 型腔 | H5: =IF(目录!G2="中文",对照!AI4,IF(目录!G2="English",对照!AJ4,对照!AI4)) -> 型芯
C6: Top | I6: Top
F8: =IF(目录!G2="中文",对照!AI5,IF(目录!G2="English",对照!AJ5,对照!AI5)) -> Operator Side 操作侧 | G8: =IF(目录!G2="中文",对照!AI5,IF(目录!G2="English",对照!AJ5,对照!AI5)) -> Operator Side 操作侧
B21: =IF(目录!G2="中文",对照!AI6,IF(目录!G2="English",对照!AJ6,对照!AI6)) -> 实测温度 | H21: =IF(目录!G2="中文",对照!AI6,IF(目录!G2="English",对照!AJ6,对照!AI6)) -> 实测温度
B22: # 1 | E22: °C | H22: # 1 | K22: °C
B23: # 2 | E23: °C | H23: # 2 | K23: °C
B24: # 3 | E24: °C | H24: # 3 | K24: °C
B25: # 4 | E25: °C | H25: # 4 | K25: °C
B26: # 5 | E26: °C | H26: # 5 | K26: °C
B27: # 6 | E27: °C | H27: # 6 | K27: °C
B28: # 7 | E28: °C | H28: # 7 | K28: °C
B29: # 8 | E29: °C | H29: # 8 | K29: °C
B30: # 9 | E30: °C | H30: # 9 | K30: °C
A33: 备注 Remark
A43: 保存期限：走模后2年

Sheet 有效粘度测试
A1: Back
A2: =IF(目录!G2="中文",对照!AL2,IF(目录!G2="English",对照!AM2,对照!AL2)) -> 注射速度优化报告 Optimized Injection Speed Report
A4: =IF(目录!G2="中文",对照!AL3,IF(目录!G2="English",对照!AM3,对照!AL3)) -> 机型 Injection Machine | E4: =IF(目录!G2="中文",对照!AL4,IF(目录!G2="English",对照!AM4,对照!AL4)) -> 注射时间 Injection time | J4: =IF(目录!G2="中文",对照!AL5,IF(目录!G2="English",对照!AM5,对照!AL5)) -> 注射压力 Injection pressure | N4: =IF(目录!G2="中文",对照!AL6,IF(目录!G2="English",对照!AM6,对照!AL6)) -> 注射速度 Injection Speed
H6: s
B9: =IF(目录!G2="中文",对照!AL6,IF(目录!G2="English",对照!AM6,对照!AL6)) -> 注射速度 Injection Speed | E9: =IF(目录!G2="中文",对照!AL4,IF(目录!G2="English",对照!AM4,对照!AL4)) -> 注射时间 Injection time | H9: s | I9: =IF(目录!G2="中文",对照!AL5,IF(目录!G2="English",对照!AM5,对照!AL5)) -> 注射压力 Injection pressure | L9: =IF(目录!G2="中文",对照!AL7,IF(目录!G2="English",对照!AM7,对照!AL7)) -> 剪切速率 Shear rate | N9: =IF(目录!G2="中文",对照!AL8,IF(目录!G2="English",对照!AM8,对照!AL8)) -> 有效粘度 Relative Viscosity | P9: =IF(目录!G2="中文",对照!AL9,IF(目录!G2="English",对照!AM9,对照!AL9)) -> 相对粘度差异 Change in Relative Viscosity | R9: =IF(目录!G2="中文",对照!AL10,IF(目录!G2="English",对照!AM10,对照!AL10)) -> 折线 | S9: =IF(目录!G2="中文",对照!AL11,IF(目录!G2="English",对照!AM11,对照!AL11)) -> 斜率
A11: 1 | R11: n/a | S11: n/a
A12: 2 | P12: =N12-N11 -> 0 | R12: 1 → 2 | S12: =P12/(L12-L11) -> #DIV/0!
A13: 3 | P13: =N13-N12 -> 0 | R13: 2 → 3 | S13: =P13/(L13-L12) -> #DIV/0!
A14: 4 | P14: =N14-N13 -> 0 | R14: 3 → 4 | S14: =P14/(L14-L13) -> #DIV/0!
A15: 5 | P15: =N15-N14 -> 0 | R15: 4 → 5 | S15: =P15/(L15-L14) -> #DIV/0!
A16: 6 | P16: =N16-N15 -> 0 | R16: 5 → 6 | S16: =P16/(L16-L15) -> #DIV/0!
A17: 7 | P17: =N17-N16 -> 0 | R17: 6 → 7 | S17: =P17/(L17-L16) -> #DIV/0!
A18: 8 | P18: =N18-N17 -> 0 | R18: 7 → 8 | S18: =P18/(L18-L17) -> #DIV/0!
A19: 9 | P19: =N19-N18 -> 0 | R19: 8 → 9 | S19: =P19/(L19-L18) -> #DIV/0!
A20: 10 | P20: =N20-N19 -> 0 | R20: 9 → 10 | S20: =P20/(L20-L19) -> #DIV/0!
A21: 11 | P21: =N21-N20 -> 0 | R21: 10 → 11 | S21: =P21/(L21-L20) -> #DIV/0!
A47: 备注 Remark
A57: 保存期限：走模后2年

Sheet 多型腔平衡测试
A1: Back
A2: =IF(目录!G2="中文",对照!AO2,IF(目录!G2="English",对照!AP2,对照!AO2)) -> 走水平衡分析报告 Short Shot Balance Report
A3: =IF(目录!G2="中文",对照!AO6,IF(目录!G2="English",对照!AP6,对照!AO6)) -> 最大重量 Maximum weight | D3: =IF(目录!G2="中文",对照!AO4,IF(目录!G2="English",对照!AP4,对照!AO4)) -> 型腔 Cavity | G3: =IF(目录!G2="中文",对照!AO7,IF(目录!G2="English",对照!AP7,对照!AO7)) -> 最小重量 Minimum weight | J3: =IF(目录!G2="中文",对照!AO4,IF(目录!G2="English",对照!AP4,对照!AO4)) -> 型腔 Cavity
A6: =IF(目录!G2="中文",对照!AO8,IF(目录!G2="English",对照!AP8,对照!AO8)) -> 平衡度 Balance | G6: =IF(目录!G2="中文",对照!AO9,IF(目录!G2="English",对照!AP9,对照!AO9)) -> 判定结果 Result
A9: 备注 Remark
A16: 填充量 Filling
A18: =IF(目录!G2="中文",对照!AO4,IF(目录!G2="English",对照!AP4,对照!AO4)) -> 型腔 Cavity | B18: =IF(目录!G2="中文",对照!AO5,IF(目录!G2="English",对照!AP5,对照!AO5)) -> 重量(g) Weight(g) | F18: =IF(目录!G2="中文",对照!AO4,IF(目录!G2="English",对照!AP4,对照!AO4)) -> 型腔 Cavity | G18: 高速(g) | I18: 中速(g) | K18: 低速(g)
A20: 1 | B20: =IF(AVERAGE(G20:L20),AVERAGE(G20:L20),NA()) -> #DIV/0! | F20: 1
A21: 2 | B21: =IF(AVERAGE(G21:L21),AVERAGE(G21:L21),NA()) -> #DIV/0! | F21: 2
A22: 3 | B22: =IF(AVERAGE(G22:L22),AVERAGE(G22:L22),NA()) -> #DIV/0! | F22: 3
A23: 4 | B23: =IF(AVERAGE(G23:L23),AVERAGE(G23:L23),NA()) -> #DIV/0! | F23: 4
A24: 5 | B24: =IF(AVERAGE(G24:L24),AVERAGE(G24:L24),NA()) -> #DIV/0! | F24: 5
A25: 6 | B25: =IF(AVERAGE(G25:L25),AVERAGE(G25:L25),NA()) -> #DIV/0! | F25: 6
A26: 7 | B26: =AVERAGE(G26:L26) -> #DIV/0! | F26: 7
A27: 8 | B27: =AVERAGE(G27:L27) -> #DIV/0! | F27: 8
A28: 9 | B28: =AVERAGE(G28:L28) -> #DIV/0! | F28: 9
A29: 10 | B29: =AVERAGE(G29:L29) -> #DIV/0! | F29: 10
A30: 11 | B30: =AVERAGE(G30:L30) -> #DIV/0! | F30: 11
A31: 12 | B31: =AVERAGE(G31:L31) -> #DIV/0! | F31: 12
A32: 13 | B32: =AVERAGE(G32:L32) -> #DIV/0! | F32: 13
A33: 14 | B33: =AVERAGE(G33:L33) -> #DIV/0! | F33: 14
A34: 15 | B34: =AVERAGE(G34:L34) -> #DIV/0! | F34: 15
A35: 16 | B35: =AVERAGE(G35:L35) -> #DIV/0! | F35: 16
A36: 17 | B36: =AVERAGE(G36:L36) -> #DIV/0! | F36: 17
A37: 18 | B37: =AVERAGE(G37:L37) -> #DIV/0! | F37: 18
... A531: 512 | B531: =AVERAGE(G531:L531) -> #DIV/0! | F531: 512
A532: 最重的 | F532: 最重的
A533: 最轻的 | F533: 最轻的
A534: 平均值 | F534: 平均值
A535: 平衡度 | F535: 平衡度
F536: 速度(mm/s)
F537: 填充时间(s)

Sheet 压力损失测试
A1: Back
A2: =IF(目录!G2="中文",对照!AR2,IF(目录!G2="English",对照!AS2,对照!AR2)) -> 压力损失报告 Pressure Loss Report
A3: =IF(目录!G2="中文",对照!AR3,IF(目录!G2="English",对照!AS3,对照!AR3)) -> 流经位置 Flow analysis | B3: =IF(目录!G2="中文",对照!AR4,IF(目录!G2="English",对照!AS4,对照!AR4)) -> 实际注射压力 Actual Injection Pressure | C3: =IF(目录!G2="中文",对照!AR5,IF(目录!G2="English",对照!AS5,对照!AR5)) -> 单位 Unit | E3: 各部位压力损失 Pressure loss of each part
E5: 填充部位 Filling Part | F5: 压力损失 Pressure Loss | G5: 单位 Unit
A43: 备注 Remark
G53: 保存期限：走模后2年

Sheet 保压压力测试
A1: Back
A2: =IF(目录!G2="中文",对照!AU2,IF(目录!G2="English",对照!AV2,对照!AU2)) -> 保压压力测试报告 Holding Pressure Test Report
A3: =IF(目录!G2="中文",对照!AU3,IF(目录!G2="English",对照!AV3,对照!AU3)) -> 优化操作者 Operator | E3: =IF(目录!G2="中文",对照!AU4,IF(目录!G2="English",对照!AV4,对照!AU4)) -> 优化日期 Date | I3: 最优保压设定区间 | O3: 当前锁模力 Curr Clamping Force | Q3: Ton
A6: =IF(目录!G2="中文",对照!AU6,IF(目录!G2="English",对照!AV6,对照!AU6)) -> 序号 Item | B6: =IF(目录!G2="中文",对照!AU7,IF(目录!G2="English",对照!AV7,对照!AU7)) -> 保压压力 Holding pressure | G6: =IF(目录!G2="中文",对照!AU9,IF(目录!G2="English",对照!AV9,对照!AU9)) -> 制品外观描述 Explanation | O6: =IF(目录!G2="中文",对照!AU10,IF(目录!G2="English",对照!AV10,对照!AU10)) -> 制品重量（g） Product weight | Q6: g
A8: 1
A9: 2
A10: 3
A11: 4
A12: 5
A13: 6
A14: 7
A15: 8
A16: 9
A17: 10
A19: 备注 Remark
O29: 保存期限：走模后2年

Sheet 浇口冻结时间测试
A1: Back
A2: =IF(目录!G2="中文",对照!AX2,IF(目录!G2="English",对照!AY2,对照!AX2)) -> 保压时间优化 Optimized Holding Time Report
A3: =IF(目录!G2="中文",对照!AU3,IF(目录!G2="English",对照!AV3,对照!AU3)) -> 优化操作者 Operator | E3: 优化日期 Optimized date | J3: =IF(目录!G2="中文",对照!AX3,IF(目录!G2="English",对照!AY3,对照!AX3)) -> 优化结果 Optimized result | N3: s
A6: 序号 | B6: 保压时间 | D6: s | E6: 平均重量 | F6: g | G6: 冷却时间 | H6: s | J6: 序号 | K6: =IF(目录!G2="中文",对照!AX8,IF(目录!G2="English",对照!AY8,对照!AX8)) -> 产品重量 Product weight (g)
A7: Item | B7: Holding time | E7: Average weight | G7: Cooling time | J7: Item | K7: #1 | L7: #2 | M7: #3
A8: 1 | J8: 1
A9: 2 | J9: 2
A10: 3 | J10: 3
A11: 4 | J11: 4
A12: 5 | J12: 5
A13: 6 | J13: 6
A14: 7 | J14: 7
A15: 8 | J15: 8
A16: 9 | J16: 9
A17: 10 | J17: 10
A33: 备注 Remark
A43: 保存期限：走模后2年

Sheet 冷却时间测试
A1: Back
A2: =IF(目录!G2="中文",对照!BA2,IF(目录!G2="English",对照!BB2,对照!BA2)) -> 冷却时间优化报告 Optimized Cooling Time Report
A3: =IF(目录!G2="中文",对照!AU3,IF(目录!G2="English",对照!AV3,对照!AU3)) -> 优化操作者 Operator | D3: =IF(目录!G2="中文",对照!AU4,IF(目录!G2="English",对照!AV4,对照!AU4)) -> 优化日期 Date | G3: =IF(目录!G2="中文",对照!BA3,IF(目录!G2="English",对照!BB3,对照!BA3)) -> 优化冷却时间 Optimized Cooling Time | J3: s
A6: =IF(目录!G2="中文",对照!AU6,IF(目录!G2="English",对照!AV6,对照!AU6)) -> 序号 Item | B6: =IF(目录!G2="中文",对照!AX7,IF(目录!G2="English",对照!AY7,对照!AX7)) -> 冷却时间 (s) Cooling time (s) | C6: =IF(目录!G2="中文",对照!BA4,IF(目录!G2="English",对照!BB4,对照!BA4)) -> 外观描述 Appearance description | G6: 表面温度(℃) | H6: 制品尺寸 | I6: 结果判定
A8: 1
A9: 2
A10: 3
A11: 4
A12: 5
A13: 6
A14: 7
A15: 8
A16: 9
A17: 10
A19: 备注 Remark
A29: 保存期限：走模后2年

Sheet 锁模力测试
A1: Back
A2: =IF(目录!G2="中文",对照!BD2,IF(目录!G2="English",对照!BE2,对照!BD2)) -> 锁模力优化报告 Optimized Clamp Force Report
A3: =IF(目录!G2="中文",对照!AU3,IF(目录!G2="English",对照!AV3,对照!AU3)) -> 优化操作者 Operator | C3: =IF(目录!G2="中文",对照!BD3,IF(目录!G2="English",对照!BE3,对照!BD3)) -> 优化的锁模力 Opt. clamp force | E3: Ton | F3: =IF(目录!G2="中文",对照!BD4,IF(目录!G2="English",对照!BE4,对照!BD4)) -> 当前最大保压压力 Cur. Max. Hld. Pres.
A6: =IF(目录!G2="中文",对照!AU4,IF(目录!G2="English",对照!AV4,对照!AU4)) -> 优化日期 Date | C6: =IF(目录!G2="中文",对照!BD5,IF(目录!G2="English",对照!BE5,对照!BD5)) -> 注塑机最高锁模力 Max. clamp force | E6: Ton
A9: =IF(目录!G2="中文",对照!AU6,IF(目录!G2="English",对照!AV6,对照!AU6)) -> 序号 Item | B9: 锁模力 (Ton) | C9: 平均重量 (g) | D9: 产品重量 Product Weight (g) | G9: =IF(目录!G2="中文",对照!BD10,IF(目录!G2="English",对照!BE10,对照!BD10)) -> 质量描述 Quality description
B10: Clmaping force | C10: Average weight | D10: #1 | E10: #2 | F10: #3
A11: 1
A12: 2
A13: 3
A14: 4
A15: 5
A16: 6
A17: 7
A18: 8
A19: 9
A20: 10
A40: 备注 Remark
H50: 保存期限：走模后2年

Sheet 周期时间测试
A1: Back
A2: =IF(目录!G2="中文",对照!BG2,IF(目录!G2="English",对照!BH2,对照!BG2)) -> 周期时间优化报告 Optimized Cycle Time Report
A4: =IF(目录!G2="中文",对照!BG3,IF(目录!G2="English",对照!BH3,对照!BG3)) -> 目标周期时间 | E4: =IF(目录!G2="中文",对照!BG4,IF(目录!G2="English",对照!BH4,对照!BG4)) -> 实际周期时间
A6: =IF(目录!G2="中文",对照!BG7,IF(目录!G2="English",对照!BH7,对照!BG7)) -> 注射时间
A7: =IF(目录!G2="中文",对照!BG8,IF(目录!G2="English",对照!BH8,对照!BG8)) -> 保压时间
A8: =IF(目录!G2="中文",对照!BG9,IF(目录!G2="English",对照!BH9,对照!BG9)) -> 冷却时间
A9: =IF(目录!G2="中文",对照!BG10,IF(目录!G2="English",对照!BH10,对照!BG10)) -> 开模时间
A10: =IF(目录!G2="中文",对照!BG11,IF(目录!G2="English",对照!BH11,对照!BG11)) -> 取产品时间
A11: =IF(目录!G2="中文",对照!BG12,IF(目录!G2="English",对照!BH12,对照!BG12)) -> 机械手取件时间
A12: =IF(目录!G2="中文",对照!BG13,IF(目录!G2="English",对照!BH13,对照!BG13)) -> 合模时间
A13: =IF(目录!G2="中文",对照!BG14,IF(目录!G2="English",对照!BH14,对照!BG14)) -> 所有周期时间
A15: =IF(目录!G2="中文",对照!BG16,IF(目录!G2="English",对照!BH16,对照!BG16)) -> 回料时间
A33: 备注 Remark
G43: 保存期限：走模后2年
